Workbook

Sheet Deckblatt
B2: neuverdrahtet – Elektro-Leistungsverzeichnis 2026
B3: Elektro Fachbetrieb – Smarte Elektrokonzepte für Alt & Neubau
B5: Firma: | C5: neuverdrahtet – Inh. Danny Berger
B6: Adresse: | C6: Donnerstr. 131, 45357 Essen
B7: Telefon: | C7: 01706398575
B8: E-Mail: | C8: neuverdrahtet@gmail.com
B9: Einsatzgebiet: | C9: Essen und Ruhrgebiet (u. a. Bochum, Mülheim a. d. Ruhr, Oberhausen, Gelsenkirchen)
B10: Stand: | C10: August 2026
B12: Hinweise zur Nutzung
B13: • Alle Preise sind Nettopreise (netto) zzgl. 19 % Mehrwertsteuer und verstehen sich als unverbindliche Richtpreise (Stand 08/2026), Preisanpassungen je nach Aufmaß, Zugänglichkeit und Materialverfügbarkeit vorbehalten.
B14: • Jedes Gewerk ist in vier Abschnitte gegliedert: A) Material einzeln, B) Arbeitsleistung / Lohn einzeln, C) Geräte / Technik einzeln (falls vorhanden), D) Mischpositionen – vorkalkulierte Komplettpreise aus Material, Arbeitszeit und Geräten.
B15: • Gelb hinterlegte Zellen in Spalte 'Menge' sind Eingabefelder: Menge eintragen, Gesamtpreis netto/brutto wird automatisch berechnet.
B16: • Stundensätze (netto): Facharbeiter/Geselle 68,00 € · Meister 89,00 € · Anfahrtspauschale 39,00 € (bereits in den Positionen berücksichtigt).
B17: • Dieses Dokument dient als Preiskatalog/Vorlage zur Angebotserstellung und ersetzt keine verbindliche Kalkulation nach Vor-Ort-Aufmaß.
B19: Inhaltsverzeichnis & Gesamtsummen je Gewerk
B20: Nr. | C20: Gewerk / Blatt | E20: Summe netto | F20: MwSt. 19% | G20: Summe brutto
B21: 1 | C21: 1. Elektroinstallation | E21: =Elektroinstallation!F55 | F21: =Elektroinstallation!G55 | G21: =Elektroinstallation!H55
B22: 2 | C22: 2. Wallbox | E22: =Wallbox!F34 | F22: =Wallbox!G34 | G22: =Wallbox!H34
B23: 3 | C23: 3. Photovoltaik (Elektroanschluss) | E23: =Photovoltaik!F31 | F23: =Photovoltaik!G31 | G23: =Photovoltaik!H31
B24: 4 | C24: 4. Beleuchtung | E24: =Beleuchtung!F30 | F24: =Beleuchtung!G30 | G24: =Beleuchtung!H30
B25: 5 | C25: 5. Smart Home (Allgemein) | E25: =SmartHome!F30 | F25: =SmartHome!G30 | G25: =SmartHome!H30
B26: 6 | C26: 6. KNX-Gebäudesystemtechnik | E26: =KNX!F35 | F26: =KNX!G35 | G26: =KNX!H35
B27: 7 | C27: 7. Mess- und Regeltechnik (MSR) | E27: =Messregeltechnik!F33 | F27: =Messregeltechnik!G33 | G27: =Messregeltechnik!H33
B28: 8 | C28: 8. Wärmepumpe (Elektroanschluss) | E28: =Waermepumpe!F29 | F28: =Waermepumpe!G29 | G28: =Waermepumpe!H29
B29: 9 | C29: 9. DGUV-Prüfung (DGUV Vorschrift 3) | E29: =DGUV!F26 | F29: =DGUV!G26 | G29: =DGUV!H26
B30: 10 | C30: 10. E-Check | E30: =ECheck!F23 | F30: =ECheck!G23 | G30: =ECheck!H23
B31: 11 | C31: 11. Wartung | E31: =Wartung!F23 | F31: =Wartung!G23 | G31: =Wartung!H23
B32: 12 | C32: 12. Sicherheitstechnik | E32: =Sicherheitstechnik!F29 | F32: =Sicherheitstechnik!G29 | G32: =Sicherheitstechnik!H29
B33: 13 | C33: 13. Brandmeldeanlagen | E33: =Brandmeldeanlagen!F31 | F33: =Brandmeldeanlagen!G31 | G33: =Brandmeldeanlagen!H31
C34: GESAMTSUMME ALLE GEWERKE | E34: =E21+E22+E23+E24+E25+E26+E27+E28+E29+E30+E31+E32+E33 | G34: =G21+G22+G23+G24+G25+G26+G27+G28+G29+G30+G31+G32+G33
B37: Beispiel – so wird die Menge eingetragen (Demo, keine echte Position)
B38: Bezeichnung | C38: Einheit | D38: Menge | E38: Einzelpreis netto | F38: Gesamtpreis netto | G38: Gesamtpreis brutto
B39: Steckdose UP komplett (Material + Montage) | C39: Stk | D39: 3 | E39: 42 | F39: =D39*E39 | G39: =D39*E39*1.19

Sheet Elektroinstallation
A1: neuverdrahtet – Elektro-Leistungsverzeichnis – 1. Elektroinstallation
A2: Alle Preise netto in Euro, Stand siehe Deckblatt. Menge (Spalte D) bitte für Angebots-/Rechnungserstellung ausfüllen.
A3: Pos. | B3: Bezeichnung | C3: Einheit | D3: Menge | E3: Einzelpreis netto | F3: Gesamtpreis netto | G3: MwSt. 19% | H3: Gesamtpreis brutto
A4: Material
A5: EI.010 | B5: NYM-J 3x1,5 mm² Installationsleitung | C5: m | E5: 2.1 | F5: =IF(D5="",0,D5*E5) | G5: =F5*0.19 | H5: =F5+G5
A6: EI.020 | B6: NYM-J 3x2,5 mm² Installationsleitung | C6: m | E6: 2.8 | F6: =IF(D6="",0,D6*E6) | G6: =F6*0.19 | H6: =F6+G6
A7: EI.030 | B7: NYM-J 5x1,5 mm² Installationsleitung | C7: m | E7: 3.6 | F7: =IF(D7="",0,D7*E7) | G7: =F7*0.19 | H7: =F7+G7
A8: EI.040 | B8: Installationsrohr flexibel (Leerrohr) M20 | C8: m | E8: 1.4 | F8: =IF(D8="",0,D8*E8) | G8: =F8*0.19 | H8: =F8+G8
A9: EI.050 | B9: Unterputzdose Standard | C9: Stk | E9: 1.8 | F9: =IF(D9="",0,D9*E9) | G9: =F9*0.19 | H9: =F9+G9
A10: EI.060 | B10: Abzweigdose Auf-/Unterputz | C10: Stk | E10: 3.2 | F10: =IF(D10="",0,D10*E10) | G10: =F10*0.19 | H10: =F10+G10
A11: EI.070 | B11: Schalter-/Steckdoseneinsatz Standard (Serie) | C11: Stk | E11: 9.5 | F11: =IF(D11="",0,D11*E11) | G11: =F11*0.19 | H11: =F11+G11
A12: EI.080 | B12: Schalter-/Steckdosenrahmen inkl. Abdeckung | C12: Stk | E12: 7.8 | F12: =IF(D12="",0,D12*E12) | G12: =F12*0.19 | H12: =F12+G12
A13: EI.090 | B13: FI-Schutzschalter (RCD) 2-polig 25A/30mA | C13: Stk | E13: 68 | F13: =IF(D13="",0,D13*E13) | G13: =F13*0.19 | H13: =F13+G13
A14: EI.100 | B14: FI/LS-Kombischalter 1-polig 16A, Typ A | C14: Stk | E14: 145 | F14: =IF(D14="",0,D14*E14) | G14: =F14*0.19 | H14: =F14+G14
A15: EI.110 | B15: Leitungsschutzschalter (LS) B16, 1-polig | C15: Stk | E15: 14.5 | F15: =IF(D15="",0,D15*E15) | G15: =F15*0.19 | H15: =F15+G15
A16: EI.120 | B16: Sicherungs-/Verteilerschrank UP, 3-reihig | C16: Stk | E16: 165 | F16: =IF(D16="",0,D16*E16) | G16: =F16*0.19 | H16: =F16+G16
... A19: EI.150 | B19: Kabelkanal / Brüstungskanal | C19: m | E19: 8.9 | F19: =IF(D19="",0,D19*E19) | G19: =F19*0.19 | H19: =F19+G19
B20: Zwischensumme – Material | F20: =SUM(F5:F19) | G20: =SUM(G5:G19) | H20: =SUM(H5:H19)
A22: Arbeitsleistung / Lohn
A23: EI.160 | B23: Facharbeiterstunde Elektroinstallation | C23: h | E23: 68 | F23: =IF(D23="",0,D23*E23) | G23: =F23*0.19 | H23: =F23+G23
A24: EI.170 | B24: Meisterstunde (Planung / Abnahme) | C24: h | E24: 89 | F24: =IF(D24="",0,D24*E24) | G24: =F24*0.19 | H24: =F24+G24
A25: EI.180 | B25: Kabel verlegen Unterputz (Schlitz stemmen, verputzen) | C25: m | E25: 12.5 | F25: =IF(D25="",0,D25*E25) | G25: =F25*0.19 | H25: =F25+G25
A26: EI.190 | B26: Kabel verlegen Aufputz / im Kabelkanal | C26: m | E26: 5.8 | F26: =IF(D26="",0,D26*E26) | G26: =F26*0.19 | H26: =F26+G26
A27: EI.200 | B27: Unterputzdose setzen inkl. Kernbohrung | C27: Stk | E27: 18 | F27: =IF(D27="",0,D27*E27) | G27: =F27*0.19 | H27: =F27+G27
A28: EI.210 | B28: Schalter/Steckdose montieren u. anschließen | C28: Stk | E28: 14 | F28: =IF(D28="",0,D28*E28) | G28: =F28*0.19 | H28: =F28+G28
A29: EI.220 | B29: Sicherungskasten anschließen u. verdrahten (je Stromkreis) | C29: Stk | E29: 32 | F29: =IF(D29="",0,D29*E29) | G29: =F29*0.19 | H29: =F29+G29
A30: EI.230 | B30: Zählerschrank-Anschluss herstellen | C30: psch. | E30: 180 | F30: =IF(D30="",0,D30*E30) | G30: =F30*0.19 | H30: =F30+G30
A31: EI.240 | B31: Anschluss Herd / Backofen (Starkstrom) | C31: Stk | E31: 65 | F31: =IF(D31="",0,D31*E31) | G31: =F31*0.19 | H31: =F31+G31
A32: EI.250 | B32: Anschluss Durchlauferhitzer | C32: Stk | E32: 55 | F32: =IF(D32="",0,D32*E32) | G32: =F32*0.19 | H32: =F32+G32
A33: EI.260 | B33: Anfahrtspauschale | C33: psch. | E33: 39 | F33: =IF(D33="",0,D33*E33) | G33: =F33*0.19 | H33: =F33+G33
A34: EI.270 | B34: Entsorgung Altmaterial | C34: psch. | E34: 45 | F34: =IF(D34="",0,D34*E34) | G34: =F34*0.19 | H34: =F34+G34
B35: Zwischensumme – Arbeitsleistung / Lohn | F35: =SUM(F23:F34) | G35: =SUM(G23:G34) | H35: =SUM(H23:H34)
A37: Geräte / Technik
A38: EI.280 | B38: Rauchwarnmelder vernetzt (funkbasiert) | C38: Stk | E38: 42 | F38: =IF(D38="",0,D38*E38) | G38: =F38*0.19 | H38: =F38+G38
A39: EI.290 | B39: Klingel-/Gegensprechanlage Set | C39: Stk | E39: 165 | F39: =IF(D39="",0,D39*E39) | G39: =F39*0.19 | H39: =F39+G39
A40: EI.300 | B40: Zeitschaltuhr / Treppenlichtautomat | C40: Stk | E40: 38 | F40: =IF(D40="",0,D40*E40) | G40: =F40*0.19 | H40: =F40+G40
A41: EI.310 | B41: Überspannungsschutz Typ 2 (SPD) | C41: Stk | E41: 95 | F41: =IF(D41="",0,D41*E41) | G41: =F41*0.19 | H41: =F41+G41
B42: Zwischensumme – Geräte / Technik | F42: =SUM(F38:F41) | G42: =SUM(G38:G41) | H42: =SUM(H38:H41)
A44: Mischpositionen (Material + Arbeit + Geräte komplett)
A45: EI.320 | B45: Steckdose UP komplett (Material + Montage) | C45: Stk | E45: 42 | F45: =IF(D45="",0,D45*E45) | G45: =F45*0.19 | H45: =F45+G45
...

Sheet Wallbox
A1: neuverdrahtet – Elektro-Leistungsverzeichnis – 2. Wallbox
A2: Alle Preise netto in Euro, Stand siehe Deckblatt. Menge (Spalte D) bitte für Angebots-/Rechnungserstellung ausfüllen.
A3: Pos. | B3: Bezeichnung | C3: Einheit | D3: Menge | E3: Einzelpreis netto | F3: Gesamtpreis netto | G3: MwSt. 19% | H3: Gesamtpreis brutto
A4: Material
A5: WB.010 | B5: Wallbox 11 kW, geeicht | C5: Stk | E5: 890 | F5: =IF(D5="",0,D5*E5) | G5: =F5*0.19 | H5: =F5+G5
A6: WB.020 | B6: Wallbox 22 kW mit Lastmanagement | C6: Stk | E6: 1490 | F6: =IF(D6="",0,D6*E6) | G6: =F6*0.19 | H6: =F6+G6
A7: WB.030 | B7: NYY-J 5x6 mm² Erdkabel | C7: m | E7: 6.8 | F7: =IF(D7="",0,D7*E7) | G7: =F7*0.19 | H7: =F7+G7
A8: WB.040 | B8: NYY-J 5x10 mm² Erdkabel | C8: m | E8: 9.6 | F8: =IF(D8="",0,D8*E8) | G8: =F8*0.19 | H8: =F8+G8
A9: WB.050 | B9: FI-Schutzschalter Typ B, 25A/30mA | C9: Stk | E9: 385 | F9: =IF(D9="",0,D9*E9) | G9: =F9*0.19 | H9: =F9+G9
A10: WB.060 | B10: LS-Schalter B16/B20/B32 | C10: Stk | E10: 16 | F10: =IF(D10="",0,D10*E10) | G10: =F10*0.19 | H10: =F10+G10
A11: WB.070 | B11: Leerrohr für Erdverlegung inkl. Kabelschutzrohr | C11: m | E11: 4.2 | F11: =IF(D11="",0,D11*E11) | G11: =F11*0.19 | H11: =F11+G11
A12: WB.080 | B12: Wallbox-Unterverteiler (Zählerschrank-Erweiterung) | C12: Stk | E12: 220 | F12: =IF(D12="",0,D12*E12) | G12: =F12*0.19 | H12: =F12+G12
A13: WB.090 | B13: Energiezähler (MID-konform) | C13: Stk | E13: 145 | F13: =IF(D13="",0,D13*E13) | G13: =F13*0.19 | H13: =F13+G13
B14: Zwischensumme – Material | F14: =SUM(F5:F13) | G14: =SUM(G5:G13) | H14: =SUM(H5:H13)
A16: Arbeitsleistung / Lohn
A17: WB.100 | B17: Facharbeiterstunde Wallbox-Montage | C17: h | E17: 68 | F17: =IF(D17="",0,D17*E17) | G17: =F17*0.19 | H17: =F17+G17
A18: WB.110 | B18: Montage Wallbox an Wand / Stele | C18: Stk | E18: 120 | F18: =IF(D18="",0,D18*E18) | G18: =F18*0.19 | H18: =F18+G18
A19: WB.120 | B19: Kabelverlegung Innen (UP/AP) | C19: m | E19: 12.5 | F19: =IF(D19="",0,D19*E19) | G19: =F19*0.19 | H19: =F19+G19
A20: WB.130 | B20: Kabelverlegung Erdreich inkl. Grabenaushub (Hand) | C20: m | E20: 28 | F20: =IF(D20="",0,D20*E20) | G20: =F20*0.19 | H20: =F20+G20
A21: WB.140 | B21: Kernbohrung Wanddurchbruch | C21: Stk | E21: 65 | F21: =IF(D21="",0,D21*E21) | G21: =F21*0.19 | H21: =F21+G21
A22: WB.150 | B22: Anmeldung / Genehmigung beim Netzbetreiber | C22: psch. | E22: 85 | F22: =IF(D22="",0,D22*E22) | G22: =F22*0.19 | H22: =F22+G22
A23: WB.160 | B23: Inbetriebnahme u. Messprotokoll (VDE 0100-600) | C23: psch. | E23: 95 | F23: =IF(D23="",0,D23*E23) | G23: =F23*0.19 | H23: =F23+G23
A24: WB.170 | B24: Anfahrtspauschale | C24: psch. | E24: 39 | F24: =IF(D24="",0,D24*E24) | G24: =F24*0.19 | H24: =F24+G24
B25: Zwischensumme – Arbeitsleistung / Lohn | F25: =SUM(F17:F24) | G25: =SUM(G17:G24) | H25: =SUM(H17:H24)
A27: Mischpositionen (Material + Arbeit + Geräte komplett)
A28: WB.180 | B28: Wallbox-Komplettpaket 11 kW, bis 15 m Kabelweg | C28: psch. | E28: 1690 | F28: =IF(D28="",0,D28*E28) | G28: =F28*0.19 | H28: =F28+G28
A29: WB.190 | B29: Wallbox-Komplettpaket 22 kW mit Lastmanagement | C29: psch. | E29: 2390 | F29: =IF(D29="",0,D29*E29) | G29: =F29*0.19 | H29: =F29+G29
A30: WB.200 | B30: Zusatzkabelweg über 15 m, Erdverlegung (je weitere m) | C30: m | E30: 38 | F30: =IF(D30="",0,D30*E30) | G30: =F30*0.19 | H30: =F30+G30
A31: WB.210 | B31: Zweite Wallbox mit Lastmanagement-Anbindung komplett | C31: psch. | E31: 990 | F31: =IF(D31="",0,D31*E31) | G31: =F31*0.19 | H31: =F31+G31
B32: Zwischensumme – Mischpositionen (Material + Arbeit + Geräte komplett) | F32: =SUM(F28:F31) | G32: =SUM(G28:G31) | H32: =SUM(H28:H31)
B34: GESAMTSUMME 2. Wallbox | F34: =F14+F25+F32 | G34: =G14+G25+G32 | H34: =H14+H25+H32

Sheet Photovoltaik
A1: neuverdrahtet – Elektro-Leistungsverzeichnis – 3. Photovoltaik (Elektroanschluss)
A2: Alle Preise netto in Euro, Stand siehe Deckblatt. Menge (Spalte D) bitte für Angebots-/Rechnungserstellung ausfüllen.
A3: Pos. | B3: Bezeichnung | C3: Einheit | D3: Menge | E3: Einzelpreis netto | F3: Gesamtpreis netto | G3: MwSt. 19% | H3: Gesamtpreis brutto
A4: Material
A5: PV.010 | B5: AC-Zählerschrank-Kombination (PV-fähig) | C5: Stk | E5: 450 | F5: =IF(D5="",0,D5*E5) | G5: =F5*0.19 | H5: =F5+G5
A6: PV.020 | B6: AC-Kabel NYM-J 5x6 mm² Wechselrichteranschluss | C6: m | E6: 6.5 | F6: =IF(D6="",0,D6*E6) | G6: =F6*0.19 | H6: =F6+G6
A7: PV.030 | B7: FI-Schutzschalter Typ B (Wechselrichter) | C7: Stk | E7: 385 | F7: =IF(D7="",0,D7*E7) | G7: =F7*0.19 | H7: =F7+G7
A8: PV.040 | B8: Überspannungsschutz Typ 1+2 (AC-Seite) | C8: Stk | E8: 165 | F8: =IF(D8="",0,D8*E8) | G8: =F8*0.19 | H8: =F8+G8
A9: PV.050 | B9: Zweirichtungszähler-Vorbereitung | C9: Stk | E9: 95 | F9: =IF(D9="",0,D9*E9) | G9: =F9*0.19 | H9: =F9+G9
A10: PV.060 | B10: Backup-/Notstromsteckdose Set | C10: Stk | E10: 245 | F10: =IF(D10="",0,D10*E10) | G10: =F10*0.19 | H10: =F10+G10
A11: PV.070 | B11: Smart-Meter-Gateway Anschlussmaterial | C11: Stk | E11: 85 | F11: =IF(D11="",0,D11*E11) | G11: =F11*0.19 | H11: =F11+G11
B12: Zwischensumme – Material | F12: =SUM(F5:F11) | G12: =SUM(G5:G11) | H12: =SUM(H5:H11)
A14: Arbeitsleistung / Lohn
A15: PV.080 | B15: Facharbeiterstunde PV-Elektroanschluss | C15: h | E15: 68 | F15: =IF(D15="",0,D15*E15) | G15: =F15*0.19 | H15: =F15+G15
A16: PV.090 | B16: Zählerschrank-Umbau für PV-Einspeisung | C16: psch. | E16: 380 | F16: =IF(D16="",0,D16*E16) | G16: =F16*0.19 | H16: =F16+G16
A17: PV.100 | B17: AC-Anschluss Wechselrichter herstellen | C17: Stk | E17: 145 | F17: =IF(D17="",0,D17*E17) | G17: =F17*0.19 | H17: =F17+G17
A18: PV.110 | B18: Anmeldung Netzbetreiber (Einspeisezusage) | C18: psch. | E18: 95 | F18: =IF(D18="",0,D18*E18) | G18: =F18*0.19 | H18: =F18+G18
A19: PV.120 | B19: Anmeldung Marktstammdatenregister | C19: psch. | E19: 45 | F19: =IF(D19="",0,D19*E19) | G19: =F19*0.19 | H19: =F19+G19
A20: PV.130 | B20: Inbetriebnahme u. Messprotokoll | C20: psch. | E20: 120 | F20: =IF(D20="",0,D20*E20) | G20: =F20*0.19 | H20: =F20+G20
A21: PV.140 | B21: Anfahrtspauschale | C21: psch. | E21: 39 | F21: =IF(D21="",0,D21*E21) | G21: =F21*0.19 | H21: =F21+G21
B22: Zwischensumme – Arbeitsleistung / Lohn | F22: =SUM(F15:F21) | G22: =SUM(G15:G21) | H22: =SUM(H15:H21)
A24: Mischpositionen (Material + Arbeit + Geräte komplett)
A25: PV.150 | B25: PV-Elektroanschluss Komplettpaket bis 10 kWp | C25: psch. | E25: 1450 | F25: =IF(D25="",0,D25*E25) | G25: =F25*0.19 | H25: =F25+G25
A26: PV.160 | B26: PV-Elektroanschluss Komplettpaket 10–30 kWp | C26: psch. | E26: 2190 | F26: =IF(D26="",0,D26*E26) | G26: =F26*0.19 | H26: =F26+G26
A27: PV.170 | B27: Speicher-Nachrüstung elektroseitig komplett | C27: psch. | E27: 890 | F27: =IF(D27="",0,D27*E27) | G27: =F27*0.19 | H27: =F27+G27
A28: PV.180 | B28: Notstrom-/Ersatzstromanschluss komplett | C28: psch. | E28: 690 | F28: =IF(D28="",0,D28*E28) | G28: =F28*0.19 | H28: =F28+G28
B29: Zwischensumme – Mischpositionen (Material + Arbeit + Geräte komplett) | F29: =SUM(F25:F28) | G29: =SUM(G25:G28) | H29: =SUM(H25:H28)
B31: GESAMTSUMME 3. Photovoltaik (Elektroanschluss) | F31: =F12+F22+F29 | G31: =G12+G22+G29 | H31: =H12+H22+H29

Sheet Beleuchtung
A1: neuverdrahtet – Elektro-Leistungsverzeichnis – 4. Beleuchtung
A2: Alle Preise netto in Euro, Stand siehe Deckblatt. Menge (Spalte D) bitte für Angebots-/Rechnungserstellung ausfüllen.
A3: Pos. | B3: Bezeichnung | C3: Einheit | D3: Menge | E3: Einzelpreis netto | F3: Gesamtpreis netto | G3: MwSt. 19% | H3: Gesamtpreis brutto
A4: Material
A5: BL.010 | B5: LED-Panel 62x62 cm, 40 W | C5: Stk | E5: 68 | F5: =IF(D5="",0,D5*E5) | G5: =F5*0.19 | H5: =F5+G5
A6: BL.020 | B6: LED-Einbaustrahler-Set (dimmbar) | C6: Stk | E6: 24 | F6: =IF(D6="",0,D6*E6) | G6: =F6*0.19 | H6: =F6+G6
A7: BL.030 | B7: Bewegungsmelder UP/AP | C7: Stk | E7: 32 | F7: =IF(D7="",0,D7*E7) | G7: =F7*0.19 | H7: =F7+G7
A8: BL.040 | B8: Dimmer-Einsatz (Phasenan-/-abschnitt) | C8: Stk | E8: 45 | F8: =IF(D8="",0,D8*E8) | G8: =F8*0.19 | H8: =F8+G8
A9: BL.050 | B9: Trafo / Netzteil LED 12V/24V | C9: Stk | E9: 38 | F9: =IF(D9="",0,D9*E9) | G9: =F9*0.19 | H9: =F9+G9
A10: BL.060 | B10: Lichtschiene 3-Phasen inkl. Zubehör | C10: m | E10: 42 | F10: =IF(D10="",0,D10*E10) | G10: =F10*0.19 | H10: =F10+G10
A11: BL.070 | B11: Pendelleuchten-Anschlussdose | C11: Stk | E11: 12 | F11: =IF(D11="",0,D11*E11) | G11: =F11*0.19 | H11: =F11+G11
B12: Zwischensumme – Material | F12: =SUM(F5:F11) | G12: =SUM(G5:G11) | H12: =SUM(H5:H11)
A14: Arbeitsleistung / Lohn
A15: BL.080 | B15: Facharbeiterstunde Beleuchtungstechnik | C15: h | E15: 68 | F15: =IF(D15="",0,D15*E15) | G15: =F15*0.19 | H15: =F15+G15
A16: BL.090 | B16: Lichtplanung / Beratung vor Ort | C16: psch. | E16: 95 | F16: =IF(D16="",0,D16*E16) | G16: =F16*0.19 | H16: =F16+G16
A17: BL.100 | B17: Leuchtenmontage (Decke / Wand) | C17: Stk | E17: 28 | F17: =IF(D17="",0,D17*E17) | G17: =F17*0.19 | H17: =F17+G17
A18: BL.110 | B18: Einbaustrahler-Montage inkl. Ausschnitt | C18: Stk | E18: 22 | F18: =IF(D18="",0,D18*E18) | G18: =F18*0.19 | H18: =F18+G18
A19: BL.120 | B19: DALI-/Bussteuerleitung verlegen | C19: m | E19: 8.5 | F19: =IF(D19="",0,D19*E19) | G19: =F19*0.19 | H19: =F19+G19
A20: BL.130 | B20: Anfahrtspauschale | C20: psch. | E20: 39 | F20: =IF(D20="",0,D20*E20) | G20: =F20*0.19 | H20: =F20+G20
B21: Zwischensumme – Arbeitsleistung / Lohn | F21: =SUM(F15:F20) | G21: =SUM(G15:G20) | H21: =SUM(H15:H20)
A23: Mischpositionen (Material + Arbeit + Geräte komplett)
A24: BL.140 | B24: Einbaustrahler-Set komplett (5 Stk. inkl. Montage) | C24: psch. | E24: 245 | F24: =IF(D24="",0,D24*E24) | G24: =F24*0.19 | H24: =F24+G24
A25: BL.150 | B25: Zimmerbeleuchtung Komplettpaket (Decke + Schalter) | C25: psch. | E25: 185 | F25: =IF(D25="",0,D25*E25) | G25: =F25*0.19 | H25: =F25+G25
A26: BL.160 | B26: Außenbeleuchtung Komplettpaket inkl. Bewegungsmelder | C26: psch. | E26: 320 | F26: =IF(D26="",0,D26*E26) | G26: =F26*0.19 | H26: =F26+G26
A27: BL.170 | B27: LED-Umrüstung pro Leuchtstelle komplett | C27: Stk | E27: 55 | F27: =IF(D27="",0,D27*E27) | G27: =F27*0.19 | H27: =F27+G27
B28: Zwischensumme – Mischpositionen (Material + Arbeit + Geräte komplett) | F28: =SUM(F24:F27) | G28: =SUM(G24:G27) | H28: =SUM(H24:H27)
B30: GESAMTSUMME 4. Beleuchtung | F30: =F12+F21+F28 | G30: =G12+G21+G28 | H30: =H12+H21+H28

Sheet SmartHome
A1: neuverdrahtet – Elektro-Leistungsverzeichnis – 5. Smart Home (Allgemein)
A2: Alle Preise netto in Euro, Stand siehe Deckblatt. Menge (Spalte D) bitte für Angebots-/Rechnungserstellung ausfüllen.
A3: Pos. | B3: Bezeichnung | C3: Einheit | D3: Menge | E3: Einzelpreis netto | F3: Gesamtpreis netto | G3: MwSt. 19% | H3: Gesamtpreis brutto
A4: Material
A5: SH.010 | B5: KNX-Universal-Aktor 4-fach | C5: Stk | E5: 145 | F5: =IF(D5="",0,D5*E5) | G5: =F5*0.19 | H5: =F5+G5
A6: SH.020 | B6: KNX-Taster 2-fach mit Display | C6: Stk | E6: 165 | F6: =IF(D6="",0,D6*E6) | G6: =F6*0.19 | H6: =F6+G6
A7: SH.030 | B7: Smart-Home-Gateway / Server | C7: Stk | E7: 320 | F7: =IF(D7="",0,D7*E7) | G7: =F7*0.19 | H7: =F7+G7
A8: SH.040 | B8: Funk-Aktor Steckdose / Schaltaktor | C8: Stk | E8: 55 | F8: =IF(D8="",0,D8*E8) | G8: =F8*0.19 | H8: =F8+G8
A9: SH.050 | B9: Rollladen-/Jalousieaktor | C9: Stk | E9: 68 | F9: =IF(D9="",0,D9*E9) | G9: =F9*0.19 | H9: =F9+G9
A10: SH.060 | B10: Heizungsaktor (Fußbodenheizung/Thermostat) | C10: Stk | E10: 58 | F10: =IF(D10="",0,D10*E10) | G10: =F10*0.19 | H10: =F10+G10
A11: SH.070 | B11: Präsenzmelder KNX | C11: Stk | E11: 95 | F11: =IF(D11="",0,D11*E11) | G11: =F11*0.19 | H11: =F11+G11
B12: Zwischensumme – Material | F12: =SUM(F5:F11) | G12: =SUM(G5:G11) | H12: =SUM(H5:H11)
A14: Arbeitsleistung / Lohn
A15: SH.080 | B15: Facharbeiterstunde Smart-Home-Installation | C15: h | E15: 68 | F15: =IF(D15="",0,D15*E15) | G15: =F15*0.19 | H15: =F15+G15
A16: SH.090 | B16: Systemplanung / Beratung | C16: psch. | E16: 120 | F16: =IF(D16="",0,D16*E16) | G16: =F16*0.19 | H16: =F16+G16
A17: SH.100 | B17: KNX-Programmierung je Raum | C17: Stk | E17: 85 | F17: =IF(D17="",0,D17*E17) | G17: =F17*0.19 | H17: =F17+G17
A18: SH.110 | B18: Inbetriebnahme Gesamtsystem | C18: psch. | E18: 220 | F18: =IF(D18="",0,D18*E18) | G18: =F18*0.19 | H18: =F18+G18
A19: SH.120 | B19: Einweisung Kunde (App / Bedienung) | C19: psch. | E19: 65 | F19: =IF(D19="",0,D19*E19) | G19: =F19*0.19 | H19: =F19+G19
A20: SH.130 | B20: Anfahrtspauschale | C20: psch. | E20: 39 | F20: =IF(D20="",0,D20*E20) | G20: =F20*0.19 | H20: =F20+G20
B21: Zwischensumme – Arbeitsleistung / Lohn | F21: =SUM(F15:F20) | G21: =SUM(G15:G20) | H21: =SUM(H15:H20)
A23: Mischpositionen (Material + Arbeit + Geräte komplett)
A24: SH.140 | B24: Smart-Home Starter-Paket (3 Räume, Licht + Rollladen) | C24: psch. | E24: 1690 | F24: =IF(D24="",0,D24*E24) | G24: =F24*0.19 | H24: =F24+G24
A25: SH.150 | B25: Raumsteuerung komplett (Licht/Heizung/Rollladen je Raum) | C25: Stk | E25: 385 | F25: =IF(D25="",0,D25*E25) | G25: =F25*0.19 | H25: =F25+G25
A26: SH.160 | B26: Rollladensteuerung komplett (Material+Montage+Programmierung) | C26: Stk | E26: 165 | F26: =IF(D26="",0,D26*E26) | G26: =F26*0.19 | H26: =F26+G26
A27: SH.170 | B27: Sprachsteuerung-Integration (Alexa/Google) komplett | C27: psch. | E27: 145 | F27: =IF(D27="",0,D27*E27) | G27: =F27*0.19 | H27: =F27+G27
B28: Zwischensumme – Mischpositionen (Material + Arbeit + Geräte komplett) | F28: =SUM(F24:F27) | G28: =SUM(G24:G27) | H28: =SUM(H24:H27)
B30: GESAMTSUMME 5. Smart Home (Allgemein) | F30: =F12+F21+F28 | G30: =G12+G21+G28 | H30: =H12+H21+H28

Sheet KNX
A1: neuverdrahtet – Elektro-Leistungsverzeichnis – 6. KNX-Gebäudesystemtechnik
A2: Alle Preise netto in Euro, Stand siehe Deckblatt. Menge (Spalte D) bitte für Angebots-/Rechnungserstellung ausfüllen.
A3: Pos. | B3: Bezeichnung | C3: Einheit | D3: Menge | E3: Einzelpreis netto | F3: Gesamtpreis netto | G3: MwSt. 19% | H3: Gesamtpreis brutto
A4: Material
A5: KX.010 | B5: KNX-Spannungsversorgung 640 mA inkl. Drossel | C5: Stk | E5: 145 | F5: =IF(D5="",0,D5*E5) | G5: =F5*0.19 | H5: =F5+G5
A6: KX.020 | B6: KNX-Busankoppler (Universal) | C6: Stk | E6: 35 | F6: =IF(D6="",0,D6*E6) | G6: =F6*0.19 | H6: =F6+G6
A7: KX.030 | B7: KNX-Universal-Binärausgang 8-fach | C7: Stk | E7: 185 | F7: =IF(D7="",0,D7*E7) | G7: =F7*0.19 | H7: =F7+G7
A8: KX.040 | B8: KNX-Jalousie-/Rollladenaktor 4-fach | C8: Stk | E8: 165 | F8: =IF(D8="",0,D8*E8) | G8: =F8*0.19 | H8: =F8+G8
A9: KX.050 | B9: KNX-Dimmaktor 4-fach | C9: Stk | E9: 195 | F9: =IF(D9="",0,D9*E9) | G9: =F9*0.19 | H9: =F9+G9
A10: KX.060 | B10: KNX-Tastsensor 4-fach mit Raumtemperaturregler | C10: Stk | E10: 185 | F10: =IF(D10="",0,D10*E10) | G10: =F10*0.19 | H10: =F10+G10
A11: KX.070 | B11: KNX-Wetterstation (Wind/Regen/Helligkeit) | C11: Stk | E11: 320 | F11: =IF(D11="",0,D11*E11) | G11: =F11*0.19 | H11: =F11+G11
A12: KX.080 | B12: KNX-IP-Router / Schnittstelle | C12: Stk | E12: 245 | F12: =IF(D12="",0,D12*E12) | G12: =F12*0.19 | H12: =F12+G12
A13: KX.090 | B13: KNX-Busleitung JY(St)Y 2x2x0,8 | C13: m | E13: 1.6 | F13: =IF(D13="",0,D13*E13) | G13: =F13*0.19 | H13: =F13+G13
A14: KX.100 | B14: KNX-Visualisierungsserver (z. B. Gira/ABB/Loxone) | C14: Stk | E14: 590 | F14: =IF(D14="",0,D14*E14) | G14: =F14*0.19 | H14: =F14+G14
B15: Zwischensumme – Material | F15: =SUM(F5:F14) | G15: =SUM(G5:G14) | H15: =SUM(H5:H14)
A17: Arbeitsleistung / Lohn
A18: KX.110 | B18: Facharbeiterstunde KNX-Installation | C18: h | E18: 68 | F18: =IF(D18="",0,D18*E18) | G18: =F18*0.19 | H18: =F18+G18
A19: KX.120 | B19: Meisterstunde KNX-Planung / ETS-Programmierung | C19: h | E19: 89 | F19: =IF(D19="",0,D19*E19) | G19: =F19*0.19 | H19: =F19+G19
A20: KX.130 | B20: KNX-Busleitung verlegen | C20: m | E20: 5.5 | F20: =IF(D20="",0,D20*E20) | G20: =F20*0.19 | H20: =F20+G20
A21: KX.140 | B21: Montage / Anschluss KNX-Gerät (Aktor/Sensor) | C21: Stk | E21: 32 | F21: =IF(D21="",0,D21*E21) | G21: =F21*0.19 | H21: =F21+G21
A22: KX.150 | B22: ETS-Projektierung je Gruppenadresse/Datenpunkt | C22: Stk | E22: 12 | F22: =IF(D22="",0,D22*E22) | G22: =F22*0.19 | H22: =F22+G22
A23: KX.160 | B23: Inbetriebnahme u. Funktionstest Gesamtanlage | C23: psch. | E23: 280 | F23: =IF(D23="",0,D23*E23) | G23: =F23*0.19 | H23: =F23+G23
A24: KX.170 | B24: Einweisung / Schulung Kunde am System | C24: psch. | E24: 95 | F24: =IF(D24="",0,D24*E24) | G24: =F24*0.19 | H24: =F24+G24
A25: KX.180 | B25: Anfahrtspauschale | C25: psch. | E25: 39 | F25: =IF(D25="",0,D25*E25) | G25: =F25*0.19 | H25: =F25+G25
B26: Zwischensumme – Arbeitsleistung / Lohn | F26: =SUM(F18:F25) | G26: =SUM(G18:G25) | H26: =SUM(H18:H25)
A28: Mischpositionen (Material + Arbeit + Geräte komplett)
A29: KX.190 | B29: KNX-Raumcontroller komplett (Taster + Aktor + Programmierung je Raum) | C29: Stk | E29: 420 | F29: =IF(D29="",0,D29*E29) | G29: =F29*0.19 | H29: =F29+G29
A30: KX.200 | B30: KNX-Jalousiesteuerung komplett je Fenster | C30: Stk | E30: 185 | F30: =IF(D30="",0,D30*E30) | G30: =F30*0.19 | H30: =F30+G30
A31: KX.210 | B31: KNX-Grundausstattung Einfamilienhaus (bis 8 Räume) komplett | C31: psch. | E31: 6900 | F31: =IF(D31="",0,D31*E31) | G31: =F31*0.19 | H31: =F31+G31
A32: KX.220 | B32: KNX-Visualisierung Komplettpaket (Server + Einrichtung + Einweisung) | C32: psch. | E32: 1290 | F32: =IF(D32="",0,D32*E32) | G32: =F32*0.19 | H32: =F32+G32
B33: Zwischensumme – Mischpositionen (Material + Arbeit + Geräte komplett) | F33: =SUM(F29:F32) | G33: =SUM(G29:G32) | H33: =SUM(H29:H32)
B35: GESAMTSUMME 6. KNX-Gebäudesystemtechnik | F35: =F15+F26+F33 | G35: =G15+G26+G33 | H35: =H15+H26+H33

Sheet Messregeltechnik
A1: neuverdrahtet – Elektro-Leistungsverzeichnis – 7. Mess- und Regeltechnik (MSR)
A2: Alle Preise netto in Euro, Stand siehe Deckblatt. Menge (Spalte D) bitte für Angebots-/Rechnungserstellung ausfüllen.
A3: Pos. | B3: Bezeichnung | C3: Einheit | D3: Menge | E3: Einzelpreis netto | F3: Gesamtpreis netto | G3: MwSt. 19% | H3: Gesamtpreis brutto
A4: Material
A5: MR.010 | B5: Temperaturfühler (PT100 / PT1000) | C5: Stk | E5: 28 | F5: =IF(D5="",0,D5*E5) | G5: =F5*0.19 | H5: =F5+G5
A6: MR.020 | B6: Feuchtefühler / Hygrostat | C6: Stk | E6: 45 | F6: =IF(D6="",0,D6*E6) | G6: =F6*0.19 | H6: =F6+G6
A7: MR.030 | B7: Drucktransmitter | C7: Stk | E7: 85 | F7: =IF(D7="",0,D7*E7) | G7: =F7*0.19 | H7: =F7+G7
A8: MR.040 | B8: Stromwandler für Energiemonitoring | C8: Stk | E8: 38 | F8: =IF(D8="",0,D8*E8) | G8: =F8*0.19 | H8: =F8+G8
A9: MR.050 | B9: Zeit-/Wochenschaltuhr digital | C9: Stk | E9: 42 | F9: =IF(D9="",0,D9*E9) | G9: =F9*0.19 | H9: =F9+G9
A10: MR.060 | B10: Raumtemperaturregler digital | C10: Stk | E10: 65 | F10: =IF(D10="",0,D10*E10) | G10: =F10*0.19 | H10: =F10+G10
A11: MR.070 | B11: SPS-Kleinsteuerung / Logikmodul | C11: Stk | E11: 185 | F11: =IF(D11="",0,D11*E11) | G11: =F11*0.19 | H11: =F11+G11
A12: MR.080 | B12: Datenlogger / Energiemonitoring-Gateway | C12: Stk | E12: 145 | F12: =IF(D12="",0,D12*E12) | G12: =F12*0.19 | H12: =F12+G12
A13: MR.090 | B13: Signalkabel (LiYCY, geschirmt) | C13: m | E13: 2.4 | F13: =IF(D13="",0,D13*E13) | G13: =F13*0.19 | H13: =F13+G13
B14: Zwischensumme – Material | F14: =SUM(F5:F13) | G14: =SUM(G5:G13) | H14: =SUM(H5:H13)
A16: Arbeitsleistung / Lohn
A17: MR.100 | B17: Facharbeiterstunde Mess- und Regeltechnik | C17: h | E17: 68 | F17: =IF(D17="",0,D17*E17) | G17: =F17*0.19 | H17: =F17+G17
A18: MR.110 | B18: Meisterstunde MSR-Planung / Inbetriebnahme | C18: h | E18: 89 | F18: =IF(D18="",0,D18*E18) | G18: =F18*0.19 | H18: =F18+G18
A19: MR.120 | B19: Montage / Anschluss Fühler oder Sensor | C19: Stk | E19: 28 | F19: =IF(D19="",0,D19*E19) | G19: =F19*0.19 | H19: =F19+G19
A20: MR.130 | B20: Verkabelung Signal-/Bussystem | C20: m | E20: 6.5 | F20: =IF(D20="",0,D20*E20) | G20: =F20*0.19 | H20: =F20+G20
A21: MR.140 | B21: Programmierung Regler / SPS | C21: psch. | E21: 165 | F21: =IF(D21="",0,D21*E21) | G21: =F21*0.19 | H21: =F21+G21
A22: MR.150 | B22: Kalibrierung / Abgleich Messkette | C22: psch. | E22: 95 | F22: =IF(D22="",0,D22*E22) | G22: =F22*0.19 | H22: =F22+G22
A23: MR.160 | B23: Inbetriebnahme u. Funktionsprüfung | C23: psch. | E23: 120 | F23: =IF(D23="",0,D23*E23) | G23: =F23*0.19 | H23: =F23+G23
A24: MR.170 | B24: Anfahrtspauschale | C24: psch. | E24: 39 | F24: =IF(D24="",0,D24*E24) | G24: =F24*0.19 | H24: =F24+G24
B25: Zwischensumme – Arbeitsleistung / Lohn | F25: =SUM(F17:F24) | G25: =SUM(G17:G24) | H25: =SUM(H17:H24)
A27: Mischpositionen (Material + Arbeit + Geräte komplett)
A28: MR.180 | B28: Energiemonitoring-Paket komplett (Zähler + Sensorik + Auswertung) | C28: psch. | E28: 890 | F28: =IF(D28="",0,D28*E28) | G28: =F28*0.19 | H28: =F28+G28
A29: MR.190 | B29: Raumtemperatur-Regelung komplett (Fühler + Regler + Programmierung) | C29: Stk | E29: 245 | F29: =IF(D29="",0,D29*E29) | G29: =F29*0.19 | H29: =F29+G29
A30: MR.200 | B30: SPS-Kleinsteuerung Komplettpaket (Material + Programmierung + Inbetriebnahme) | C30: psch. | E30: 1290 | F30: =IF(D30="",0,D30*E30) | G30: =F30*0.19 | H30: =F30+G30
B31: Zwischensumme – Mischpositionen (Material + Arbeit + Geräte komplett) | F31: =SUM(F28:F30) | G31: =SUM(G28:G30) | H31: =SUM(H28:H30)
B33: GESAMTSUMME 7. Mess- und Regeltechnik (MSR) | F33: =F14+F25+F31 | G33: =G14+G25+G31 | H33: =H14+H25+H31

Sheet Waermepumpe
A1: neuverdrahtet – Elektro-Leistungsverzeichnis – 8. Wärmepumpe (Elektroanschluss)
A2: Alle Preise netto in Euro, Stand siehe Deckblatt. Menge (Spalte D) bitte für Angebots-/Rechnungserstellung ausfüllen.
A3: Pos. | B3: Bezeichnung | C3: Einheit | D3: Menge | E3: Einzelpreis netto | F3: Gesamtpreis netto | G3: MwSt. 19% | H3: Gesamtpreis brutto
A4: Material
A5: WP.010 | B5: Zählerschrank-Erweiterung für Wärmepumpe | C5: Stk | E5: 220 | F5: =IF(D5="",0,D5*E5) | G5: =F5*0.19 | H5: =F5+G5
A6: WP.020 | B6: Rundsteuerempfänger-Vorbereitung / Klemmen | C6: Stk | E6: 45 | F6: =IF(D6="",0,D6*E6) | G6: =F6*0.19 | H6: =F6+G6
A7: WP.030 | B7: Lastabwurfrelais (§14a EnWG) | C7: Stk | E7: 165 | F7: =IF(D7="",0,D7*E7) | G7: =F7*0.19 | H7: =F7+G7
A8: WP.040 | B8: NYY-J 5x6 mm² Zuleitung Außeneinheit | C8: m | E8: 6.8 | F8: =IF(D8="",0,D8*E8) | G8: =F8*0.19 | H8: =F8+G8
A9: WP.050 | B9: Steuerleitung (LiYCY) Innen-/Außeneinheit | C9: m | E9: 3.2 | F9: =IF(D9="",0,D9*E9) | G9: =F9*0.19 | H9: =F9+G9
A10: WP.060 | B10: LS-Schalter / FI für WP-Stromkreis | C10: Stk | E10: 85 | F10: =IF(D10="",0,D10*E10) | G10: =F10*0.19 | H10: =F10+G10
A11: WP.070 | B11: Potentialausgleich-Zubehör Außeneinheit | C11: Stk | E11: 28 | F11: =IF(D11="",0,D11*E11) | G11: =F11*0.19 | H11: =F11+G11
B12: Zwischensumme – Material | F12: =SUM(F5:F11) | G12: =SUM(G5:G11) | H12: =SUM(H5:H11)
A14: Arbeitsleistung / Lohn
A15: WP.080 | B15: Facharbeiterstunde Wärmepumpen-Elektroanschluss | C15: h | E15: 68 | F15: =IF(D15="",0,D15*E15) | G15: =F15*0.19 | H15: =F15+G15
A16: WP.090 | B16: Elektroanschluss Außeneinheit herstellen | C16: psch. | E16: 220 | F16: =IF(D16="",0,D16*E16) | G16: =F16*0.19 | H16: =F16+G16
A17: WP.100 | B17: Elektroanschluss Innen-/Speichereinheit | C17: psch. | E17: 165 | F17: =IF(D17="",0,D17*E17) | G17: =F17*0.19 | H17: =F17+G17
A18: WP.110 | B18: Kabelverlegung Innen / Außen | C18: m | E18: 12.5 | F18: =IF(D18="",0,D18*E18) | G18: =F18*0.19 | H18: =F18+G18
A19: WP.120 | B19: Anmeldung Netzbetreiber (§14a steuerbare Verbrauchseinrichtung) | C19: psch. | E19: 95 | F19: =IF(D19="",0,D19*E19) | G19: =F19*0.19 | H19: =F19+G19
A20: WP.130 | B20: Inbetriebnahme u. Funktionsprüfung | C20: psch. | E20: 120 | F20: =IF(D20="",0,D20*E20) | G20: =F20*0.19 | H20: =F20+G20
A21: WP.140 | B21: Anfahrtspauschale | C21: psch. | E21: 39 | F21: =IF(D21="",0,D21*E21) | G21: =F21*0.19 | H21: =F21+G21
B22: Zwischensumme – Arbeitsleistung / Lohn | F22: =SUM(F15:F21) | G22: =SUM(G15:G21) | H22: =SUM(H15:H21)
A24: Mischpositionen (Material + Arbeit + Geräte komplett)
A25: WP.150 | B25: Wärmepumpen-Elektroanschluss Komplettpaket | C25: psch. | E25: 1290 | F25: =IF(D25="",0,D25*E25) | G25: =F25*0.19 | H25: =F25+G25
A26: WP.160 | B26: Zählerschrank-Erweiterung komplett für WP + PV kombiniert | C26: psch. | E26: 590 | F26: =IF(D26="",0,D26*E26) | G26: =F26*0.19 | H26: =F26+G26
B27: Zwischensumme – Mischpositionen (Material + Arbeit + Geräte komplett) | F27: =SUM(F25:F26) | G27: =SUM(G25:G26) | H27: =SUM(H25:H26)
B29: GESAMTSUMME 8. Wärmepumpe (Elektroanschluss) | F29: =F12+F22+F27 | G29: =G12+G22+G27 | H29: =H12+H22+H27

Sheet DGUV
A1: neuverdrahtet – Elektro-Leistungsverzeichnis – 9. DGUV-Prüfung (DGUV Vorschrift 3)
A2: Alle Preise netto in Euro, Stand siehe Deckblatt. Menge (Spalte D) bitte für Angebots-/Rechnungserstellung ausfüllen.
A3: Pos. | B3: Bezeichnung | C3: Einheit | D3: Menge | E3: Einzelpreis netto | F3: Gesamtpreis netto | G3: MwSt. 19% | H3: Gesamtpreis brutto
A4: Material
A5: DG.010 | B5: Prüfplakette (Anlage / Betriebsmittel) | C5: Stk | E5: 1.2 | F5: =IF(D5="",0,D5*E5) | G5: =F5*0.19 | H5: =F5+G5
A6: DG.020 | B6: Prüfetikett mit Barcode / QR | C6: Stk | E6: 1.8 | F6: =IF(D6="",0,D6*E6) | G6: =F6*0.19 | H6: =F6+G6
B7: Zwischensumme – Material | F7: =SUM(F5:F6) | G7: =SUM(G5:G6) | H7: =SUM(H5:H6)
A9: Arbeitsleistung / Lohn
A10: DG.030 | B10: Facharbeiterstunde Prüftechnik | C10: h | E10: 68 | F10: =IF(D10="",0,D10*E10) | G10: =F10*0.19 | H10: =F10+G10
A11: DG.040 | B11: Prüfung ortsfeste elektrische Anlage (Grundpreis) | C11: psch. | E11: 145 | F11: =IF(D11="",0,D11*E11) | G11: =F11*0.19 | H11: =F11+G11
A12: DG.050 | B12: Prüfung ortsveränderliches Betriebsmittel (je Gerät) | C12: Stk | E12: 4.5 | F12: =IF(D12="",0,D12*E12) | G12: =F12*0.19 | H12: =F12+G12
A13: DG.060 | B13: Prüfung Maschine / Anlage (je Maschine) | C13: Stk | E13: 35 | F13: =IF(D13="",0,D13*E13) | G13: =F13*0.19 | H13: =F13+G13
A14: DG.070 | B14: Prüfung Schaltschrank / Verteilung | C14: Stk | E14: 65 | F14: =IF(D14="",0,D14*E14) | G14: =F14*0.19 | H14: =F14+G14
A15: DG.080 | B15: Dokumentation u. Prüfbericht | C15: psch. | E15: 45 | F15: =IF(D15="",0,D15*E15) | G15: =F15*0.19 | H15: =F15+G15
A16: DG.090 | B16: Mängelbeseitigung (Kleinreparatur, je angef. Stunde) | C16: h | E16: 68 | F16: =IF(D16="",0,D16*E16) | G16: =F16*0.19 | H16: =F16+G16
A17: DG.100 | B17: Anfahrtspauschale | C17: psch. | E17: 39 | F17: =IF(D17="",0,D17*E17) | G17: =F17*0.19 | H17: =F17+G17
B18: Zwischensumme – Arbeitsleistung / Lohn | F18: =SUM(F10:F17) | G18: =SUM(G10:G17) | H18: =SUM(H10:H17)
A20: Mischpositionen (Material + Arbeit + Geräte komplett)
A21: DG.110 | B21: DGUV-V3-Prüfpaket Kleinbetrieb (bis 50 Geräte) | C21: psch. | E21: 390 | F21: =IF(D21="",0,D21*E21) | G21: =F21*0.19 | H21: =F21+G21
A22: DG.120 | B22: DGUV-V3-Prüfpaket Mittelbetrieb (bis 150 Geräte) | C22: psch. | E22: 890 | F22: =IF(D22="",0,D22*E22) | G22: =F22*0.19 | H22: =F22+G22
A23: DG.130 | B23: Wiederholungsprüfung ortsfeste Anlage komplett | C23: psch. | E23: 245 | F23: =IF(D23="",0,D23*E23) | G23: =F23*0.19 | H23: =F23+G23
B24: Zwischensumme – Mischpositionen (Material + Arbeit + Geräte komplett) | F24: =SUM(F21:F23) | G24: =SUM(G21:G23) | H24: =SUM(H21:H23)
B26: GESAMTSUMME 9. DGUV-Prüfung (DGUV Vorschrift 3) | F26: =F7+F18+F24 | G26: =G7+G18+G24 | H26: =H7+H18+H24

Sheet ECheck
A1: neuverdrahtet – Elektro-Leistungsverzeichnis – 10. E-Check
A2: Alle Preise netto in Euro, Stand siehe Deckblatt. Menge (Spalte D) bitte für Angebots-/Rechnungserstellung ausfüllen.
A3: Pos. | B3: Bezeichnung | C3: Einheit | D3: Menge | E3: Einzelpreis netto | F3: Gesamtpreis netto | G3: MwSt. 19% | H3: Gesamtpreis brutto
A4: Material
A5: EC.010 | B5: Prüfplakette E-Check | C5: Stk | E5: 1.2 | F5: =IF(D5="",0,D5*E5) | G5: =F5*0.19 | H5: =F5+G5
B6: Zwischensumme – Material | F6: =SUM(F5:F5) | G6: =SUM(G5:G5) | H6: =SUM(H5:H5)
A8: Arbeitsleistung / Lohn
A9: EC.020 | B9: Facharbeiterstunde E-Check | C9: h | E9: 68 | F9: =IF(D9="",0,D9*E9) | G9: =F9*0.19 | H9: =F9+G9
A10: EC.030 | B10: E-Check Wohnung (bis 80 m²) | C10: psch. | E10: 165 | F10: =IF(D10="",0,D10*E10) | G10: =F10*0.19 | H10: =F10+G10
A11: EC.040 | B11: E-Check Einfamilienhaus | C11: psch. | E11: 245 | F11: =IF(D11="",0,D11*E11) | G11: =F11*0.19 | H11: =F11+G11
A12: EC.050 | B12: E-Check Gewerbe (Grundpreis, je nach Größe) | C12: psch. | E12: 320 | F12: =IF(D12="",0,D12*E12) | G12: =F12*0.19 | H12: =F12+G12
A13: EC.060 | B13: Thermografie-Zusatzprüfung | C13: psch. | E13: 145 | F13: =IF(D13="",0,D13*E13) | G13: =F13*0.19 | H13: =F13+G13
A14: EC.070 | B14: Prüfprotokoll u. Dokumentation | C14: psch. | E14: 35 | F14: =IF(D14="",0,D14*E14) | G14: =F14*0.19 | H14: =F14+G14
A15: EC.080 | B15: Anfahrtspauschale | C15: psch. | E15: 39 | F15: =IF(D15="",0,D15*E15) | G15: =F15*0.19 | H15: =F15+G15
B16: Zwischensumme – Arbeitsleistung / Lohn | F16: =SUM(F9:F15) | G16: =SUM(G9:G15) | H16: =SUM(H9:H15)
A18: Mischpositionen (Material + Arbeit + Geräte komplett)
A19: EC.090 | B19: E-Check Komplettpaket Wohnung inkl. Protokoll u. Plakette | C19: psch. | E19: 195 | F19: =IF(D19="",0,D19*E19) | G19: =F19*0.19 | H19: =F19+G19
A20: EC.100 | B20: E-Check Komplettpaket Haus inkl. Thermografie | C20: psch. | E20: 365 | F20: =IF(D20="",0,D20*E20) | G20: =F20*0.19 | H20: =F20+G20
B21: Zwischensumme – Mischpositionen (Material + Arbeit + Geräte komplett) | F21: =SUM(F19:F20) | G21: =SUM(G19:G20) | H21: =SUM(H19:H20)
B23: GESAMTSUMME 10. E-Check | F23: =F6+F16+F21 | G23: =G6+G16+G21 | H23: =H6+H16+H21

Sheet Wartung
A1: neuverdrahtet – Elektro-Leistungsverzeichnis – 11. Wartung
A2: Alle Preise netto in Euro, Stand siehe Deckblatt. Menge (Spalte D) bitte für Angebots-/Rechnungserstellung ausfüllen.
A3: Pos. | B3: Bezeichnung | C3: Einheit | D3: Menge | E3: Einzelpreis netto | F3: Gesamtpreis netto | G3: MwSt. 19% | H3: Gesamtpreis brutto
A4: Arbeitsleistung / Lohn
A5: WT.010 | B5: Facharbeiterstunde Wartung / Service | C5: h | E5: 68 | F5: =IF(D5="",0,D5*E5) | G5: =F5*0.19 | H5: =F5+G5
A6: WT.020 | B6: Wartung Elektroinstallation (jährlich, Grundpreis) | C6: psch. | E6: 145 | F6: =IF(D6="",0,D6*E6) | G6: =F6*0.19 | H6: =F6+G6
A7: WT.030 | B7: Wartung PV-Anlage (elektroseitig, jährlich) | C7: psch. | E7: 185 | F7: =IF(D7="",0,D7*E7) | G7: =F7*0.19 | H7: =F7+G7
A8: WT.040 | B8: Wartung Wallbox (jährlich) | C8: psch. | E8: 95 | F8: =IF(D8="",0,D8*E8) | G8: =F8*0.19 | H8: =F8+G8
A9: WT.050 | B9: Wartung Wärmepumpe (elektroseitig, jährlich) | C9: psch. | E9: 95 | F9: =IF(D9="",0,D9*E9) | G9: =F9*0.19 | H9: =F9+G9
A10: WT.060 | B10: Wartung Smart-Home-System (jährlich) | C10: psch. | E10: 145 | F10: =IF(D10="",0,D10*E10) | G10: =F10*0.19 | H10: =F10+G10
A11: WT.070 | B11: Wartung Beleuchtungsanlage (jährlich) | C11: psch. | E11: 85 | F11: =IF(D11="",0,D11*E11) | G11: =F11*0.19 | H11: =F11+G11
A12: WT.080 | B12: Störungsbehebung (Grundpreis + Zeit) | C12: psch. | E12: 65 | F12: =IF(D12="",0,D12*E12) | G12: =F12*0.19 | H12: =F12+G12
A13: WT.090 | B13: Thermografie-Untersuchung Verteilung | C13: psch. | E13: 165 | F13: =IF(D13="",0,D13*E13) | G13: =F13*0.19 | H13: =F13+G13
A14: WT.100 | B14: Anfahrtspauschale | C14: psch. | E14: 39 | F14: =IF(D14="",0,D14*E14) | G14: =F14*0.19 | H14: =F14+G14
B15: Zwischensumme – Arbeitsleistung / Lohn | F15: =SUM(F5:F14) | G15: =SUM(G5:G14) | H15: =SUM(H5:H14)
A17: Mischpositionen (Material + Arbeit + Geräte komplett)
A18: WT.110 | B18: Wartungsvertrag Basic (1x jährlich, 1 Gewerk) | C18: psch./Jahr | E18: 185 | F18: =IF(D18="",0,D18*E18) | G18: =F18*0.19 | H18: =F18+G18
A19: WT.120 | B19: Wartungsvertrag Komfort (1x jährlich, bis 3 Gewerke) | C19: psch./Jahr | E19: 420 | F19: =IF(D19="",0,D19*E19) | G19: =F19*0.19 | H19: =F19+G19
A20: WT.130 | B20: Wartungsvertrag Premium (2x jährlich, alle Gewerke inkl. Thermografie) | C20: psch./Jahr | E20: 890 | F20: =IF(D20="",0,D20*E20) | G20: =F20*0.19 | H20: =F20+G20
B21: Zwischensumme – Mischpositionen (Material + Arbeit + Geräte komplett) | F21: =SUM(F18:F20) | G21: =SUM(G18:G20) | H21: =SUM(H18:H20)
B23: GESAMTSUMME 11. Wartung | F23: =F15+F21 | G23: =G15+G21 | H23: =H15+H21

Sheet Sicherheitstechnik
A1: neuverdrahtet – Elektro-Leistungsverzeichnis – 12. Sicherheitstechnik
A2: Alle Preise netto in Euro, Stand siehe Deckblatt. Menge (Spalte D) bitte für Angebots-/Rechnungserstellung ausfüllen.
A3: Pos. | B3: Bezeichnung | C3: Einheit | D3: Menge | E3: Einzelpreis netto | F3: Gesamtpreis netto | G3: MwSt. 19% | H3: Gesamtpreis brutto
A4: Material
A5: ST.010 | B5: Alarmzentrale (Funk/Draht, modular) | C5: Stk | E5: 320 | F5: =IF(D5="",0,D5*E5) | G5: =F5*0.19 | H5: =F5+G5
A6: ST.020 | B6: Bewegungsmelder Alarm (Innen) | C6: Stk | E6: 55 | F6: =IF(D6="",0,D6*E6) | G6: =F6*0.19 | H6: =F6+G6
A7: ST.030 | B7: Tür-/Fensterkontakt (Funk) | C7: Stk | E7: 32 | F7: =IF(D7="",0,D7*E7) | G7: =F7*0.19 | H7: =F7+G7
A8: ST.040 | B8: Sirene Innen / Außen | C8: Stk | E8: 85 | F8: =IF(D8="",0,D8*E8) | G8: =F8*0.19 | H8: =F8+G8
A9: ST.050 | B9: Überwachungskamera (IP, PoE) | C9: Stk | E9: 145 | F9: =IF(D9="",0,D9*E9) | G9: =F9*0.19 | H9: =F9+G9
A10: ST.060 | B10: Bedienteil / Tastatur | C10: Stk | E10: 95 | F10: =IF(D10="",0,D10*E10) | G10: =F10*0.19 | H10: =F10+G10
A11: ST.070 | B11: Notstromversorgung (Akku-Backup) | C11: Stk | E11: 65 | F11: =IF(D11="",0,D11*E11) | G11: =F11*0.19 | H11: =F11+G11
B12: Zwischensumme – Material | F12: =SUM(F5:F11) | G12: =SUM(G5:G11) | H12: =SUM(H5:H11)
A14: Arbeitsleistung / Lohn
A15: ST.080 | B15: Facharbeiterstunde Sicherheitstechnik | C15: h | E15: 68 | F15: =IF(D15="",0,D15*E15) | G15: =F15*0.19 | H15: =F15+G15
A16: ST.090 | B16: Montage Alarmzentrale | C16: Stk | E16: 120 | F16: =IF(D16="",0,D16*E16) | G16: =F16*0.19 | H16: =F16+G16
A17: ST.100 | B17: Montage / Anschluss Melder/Kontakt je Stück | C17: Stk | E17: 25 | F17: =IF(D17="",0,D17*E17) | G17: =F17*0.19 | H17: =F17+G17
A18: ST.110 | B18: Programmierung / Inbetriebnahme Gesamtsystem | C18: psch. | E18: 165 | F18: =IF(D18="",0,D18*E18) | G18: =F18*0.19 | H18: =F18+G18
A19: ST.120 | B19: Einweisung Kunde | C19: psch. | E19: 45 | F19: =IF(D19="",0,D19*E19) | G19: =F19*0.19 | H19: =F19+G19
A20: ST.130 | B20: Anfahrtspauschale | C20: psch. | E20: 39 | F20: =IF(D20="",0,D20*E20) | G20: =F20*0.19 | H20: =F20+G20
B21: Zwischensumme – Arbeitsleistung / Lohn | F21: =SUM(F15:F20) | G21: =SUM(G15:G20) | H21: =SUM(H15:H20)
A23: Mischpositionen (Material + Arbeit + Geräte komplett)
A24: ST.140 | B24: Alarmanlagen-Komplettpaket Wohnung (bis 4 Melder) | C24: psch. | E24: 990 | F24: =IF(D24="",0,D24*E24) | G24: =F24*0.19 | H24: =F24+G24
A25: ST.150 | B25: Alarmanlagen-Komplettpaket Haus (bis 8 Melder + 2 Kameras) | C25: psch. | E25: 1890 | F25: =IF(D25="",0,D25*E25) | G25: =F25*0.19 | H25: =F25+G25
A26: ST.160 | B26: Kamera-Nachrüstung komplett (je Kamera) | C26: Stk | E26: 220 | F26: =IF(D26="",0,D26*E26) | G26: =F26*0.19 | H26: =F26+G26
B27: Zwischensumme – Mischpositionen (Material + Arbeit + Geräte komplett) | F27: =SUM(F24:F26) | G27: =SUM(G24:G26) | H27: =SUM(H24:H26)
B29: GESAMTSUMME 12. Sicherheitstechnik | F29: =F12+F21+F27 | G29: =G12+G21+G27 | H29: =H12+H21+H27

Sheet Brandmeldeanlagen
A1: neuverdrahtet – Elektro-Leistungsverzeichnis – 13. Brandmeldeanlagen
A2: Alle Preise netto in Euro, Stand siehe Deckblatt. Menge (Spalte D) bitte für Angebots-/Rechnungserstellung ausfüllen.
A3: Pos. | B3: Bezeichnung | C3: Einheit | D3: Menge | E3: Einzelpreis netto | F3: Gesamtpreis netto | G3: MwSt. 19% | H3: Gesamtpreis brutto
A4: Material
A5: BM.010 | B5: Rauchwarnmelder vernetzt (Funk, VdS) | C5: Stk | E5: 45 | F5: =IF(D5="",0,D5*E5) | G5: =F5*0.19 | H5: =F5+G5
A6: BM.020 | B6: Wärmemelder (VdS-anerkannt) | C6: Stk | E6: 58 | F6: =IF(D6="",0,D6*E6) | G6: =F6*0.19 | H6: =F6+G6
A7: BM.030 | B7: Brandmeldezentrale (Kleinanlage, modular) | C7: Stk | E7: 890 | F7: =IF(D7="",0,D7*E7) | G7: =F7*0.19 | H7: =F7+G7
A8: BM.040 | B8: Handfeuermelder (Druckknopfmelder) | C8: Stk | E8: 65 | F8: =IF(D8="",0,D8*E8) | G8: =F8*0.19 | H8: =F8+G8
A9: BM.050 | B9: Alarmsirene / Blitzleuchte | C9: Stk | E9: 95 | F9: =IF(D9="",0,D9*E9) | G9: =F9*0.19 | H9: =F9+G9
A10: BM.060 | B10: Funktionserhaltkabel (E30/E90) | C10: m | E10: 8.5 | F10: =IF(D10="",0,D10*E10) | G10: =F10*0.19 | H10: =F10+G10
A11: BM.070 | B11: Feuerwehr-Bedienfeld (FBF) | C11: Stk | E11: 320 | F11: =IF(D11="",0,D11*E11) | G11: =F11*0.19 | H11: =F11+G11
B12: Zwischensumme – Material | F12: =SUM(F5:F11) | G12: =SUM(G5:G11) | H12: =SUM(H5:H11)
A14: Arbeitsleistung / Lohn
A15: BM.080 | B15: Facharbeiterstunde Brandmeldetechnik | C15: h | E15: 68 | F15: =IF(D15="",0,D15*E15) | G15: =F15*0.19 | H15: =F15+G15
A16: BM.090 | B16: Montage Brandmeldezentrale | C16: psch. | E16: 320 | F16: =IF(D16="",0,D16*E16) | G16: =F16*0.19 | H16: =F16+G16
A17: BM.100 | B17: Montage Melder je Stück | C17: Stk | E17: 28 | F17: =IF(D17="",0,D17*E17) | G17: =F17*0.19 | H17: =F17+G17
A18: BM.110 | B18: Verkabelung Funktionserhalt (je m) | C18: m | E18: 6.5 | F18: =IF(D18="",0,D18*E18) | G18: =F18*0.19 | H18: =F18+G18
A19: BM.120 | B19: Programmierung / Inbetriebnahme BMA | C19: psch. | E19: 280 | F19: =IF(D19="",0,D19*E19) | G19: =F19*0.19 | H19: =F19+G19
A20: BM.130 | B20: Abnahme durch Sachverständigen (Koordination) | C20: psch. | E20: 220 | F20: =IF(D20="",0,D20*E20) | G20: =F20*0.19 | H20: =F20+G20
A21: BM.140 | B21: Wartung BMA (jährlich, DIN 14675) | C21: psch. | E21: 245 | F21: =IF(D21="",0,D21*E21) | G21: =F21*0.19 | H21: =F21+G21
A22: BM.150 | B22: Anfahrtspauschale | C22: psch. | E22: 39 | F22: =IF(D22="",0,D22*E22) | G22: =F22*0.19 | H22: =F22+G22
B23: Zwischensumme – Arbeitsleistung / Lohn | F23: =SUM(F15:F22) | G23: =SUM(G15:G22) | H23: =SUM(H15:H22)
A25: Mischpositionen (Material + Arbeit + Geräte komplett)
A26: BM.160 | B26: Rauchwarnmelder-Paket Wohnung (bis 6 Melder, vernetzt, komplett) | C26: psch. | E26: 490 | F26: =IF(D26="",0,D26*E26) | G26: =F26*0.19 | H26: =F26+G26
A27: BM.170 | B27: Brandmeldeanlage-Komplettpaket Gewerbe klein (bis 15 Melder) | C27: psch. | E27: 3890 | F27: =IF(D27="",0,D27*E27) | G27: =F27*0.19 | H27: =F27+G27
A28: BM.180 | B28: Wartungspaket BMA jährlich komplett | C28: psch./Jahr | E28: 320 | F28: =IF(D28="",0,D28*E28) | G28: =F28*0.19 | H28: =F28+G28
B29: Zwischensumme – Mischpositionen (Material + Arbeit + Geräte komplett) | F29: =SUM(F26:F28) | G29: =SUM(G26:G28) | H29: =SUM(H26:H28)
B31: GESAMTSUMME 13. Brandmeldeanlagen | F31: =F12+F23+F29 | G31: =G12+G23+G29 | H31: =H12+H23+H29
